Workbook

Sheet Municipality Master
A1: Municipality | B1: State | C1: County | D1: Population | E1: Priority Tier | F1: Research Status | G1: Researcher | H1: Date Started | I1: Date Completed | J1: Has Existing Data | K1: Data Source
A2: Chicago | B2: IL | C2: Cook | D2: 2700000 | E2: A - High Priority | F2: Complete | J2: Yes | K2: AI Estimate (Not Verified)
A3: Aurora | B3: IL | C3: Kane/DuPage | D3: 197000 | E3: A - High Priority | F3: Complete | J3: Yes | K3: AI Estimate (Not Verified)
A4: Naperville | B4: IL | C4: DuPage/Will | D4: 149000 | E4: A - High Priority | F4: Complete | J4: Yes | K4: AI Estimate (Not Verified)
A5: Joliet | B5: IL | C5: Will | D5: 148000 | E5: A - High Priority | F5: Complete | J5: Yes | K5: AI Estimate (Not Verified)
A6: Rockford | B6: IL | C6: Winnebago | D6: 146000 | E6: A - High Priority | F6: Not Started | J6: No
A7: Springfield | B7: IL | C7: Sangamon | D7: 114000 | E7: A - High Priority | F7: Not Started | J7: No
A8: Elgin | B8: IL | C8: Kane/Cook | D8: 112000 | E8: A - High Priority | F8: Not Started | J8: No
A9: Peoria | B9: IL | C9: Peoria | D9: 110000 | E9: A - High Priority | F9: Not Started | J9: No
A10: Champaign | B10: IL | C10: Champaign | D10: 88000 | E10: A - High Priority | F10: Not Started | J10: No
A11: Waukegan | B11: IL | C11: Lake | D11: 87000 | E11: A - High Priority | F11: Complete | J11: Yes | K11: AI Estimate (Not Verified)
A12: Cicero | B12: IL | C12: Cook | D12: 84000 | E12: A - High Priority | F12: Complete | J12: Yes | K12: AI Estimate (Not Verified)
A13: Bloomington | B13: IL | C13: McLean | D13: 78000 | E13: A - High Priority | F13: Not Started | J13: No
A14: Arlington Heights | B14: IL | C14: Cook | D14: 76000 | E14: A - High Priority | F14: Complete | J14: Yes | K14: AI Estimate (Not Verified)
A15: Evanston | B15: IL | C15: Cook | D15: 74000 | E15: A - High Priority | F15: Complete | J15: Yes | K15: AI Estimate (Not Verified)
A16: Schaumburg | B16: IL | C16: Cook/DuPage | D16: 74000 | E16: A - High Priority | F16: Complete | J16: Yes | K16: AI Estimate (Not Verified)
A17: Bolingbrook | B17: IL | C17: Will/DuPage | D17: 73000 | E17: A - High Priority | F17: Complete | J17: Yes | K17: AI Estimate (Not Verified)
A18: Decatur | B18: IL | C18: Macon | D18: 70000 | E18: A - High Priority | F18: Not Started | J18: No
A19: Palatine | B19: IL | C19: Cook | D19: 68000 | E19: A - High Priority | F19: Complete | J19: Yes | K19: AI Estimate (Not Verified)
A20: Skokie | B20: IL | C20: Cook | D20: 65000 | E20: A - High Priority | F20: Complete | J20: Yes | K20: AI Estimate (Not Verified)
A21: Orland Park | B21: IL | C21: Cook | D21: 58000 | E21: A - High Priority | F21: Complete | J21: Yes | K21: AI Estimate (Not Verified)
A22: Des Plaines | B22: IL | C22: Cook | D22: 58000 | E22: A - High Priority | F22: Complete | J22: Yes | K22: AI Estimate (Not Verified)
A23: Tinley Park | B23: IL | C23: Cook | D23: 57000 | E23: A - High Priority | F23: Complete | J23: Yes | K23: AI Estimate (Not Verified)
A24: Oak Lawn | B24: IL | C24: Cook | D24: 57000 | E24: A - High Priority | F24: Not Started | J24: No
A25: Berwyn | B25: IL | C25: Cook | D25: 55000 | E25: A - High Priority | F25: Complete | J25: Yes | K25: AI Estimate (Not Verified)
A26: Mount Prospect | B26: IL | C26: Cook | D26: 54000 | E26: A - High Priority | F26: Complete | J26: Yes | K26: AI Estimate (Not Verified)
A27: Wheaton | B27: IL | C27: DuPage | D27: 53000 | E27: A - High Priority | F27: Complete | J27: Yes | K27: AI Estimate (Not Verified)
A28: Hoffman Estates | B28: IL | C28: Cook | D28: 52000 | E28: A - High Priority | F28: Complete | J28: Yes | K28: AI Estimate (Not Verified)
A29: Oak Park | B29: IL | C29: Cook | D29: 52000 | E29: A - High Priority | F29: Complete | J29: Yes | K29: AI Estimate (Not Verified)
A30: Normal | B30: IL | C30: McLean | D30: 52000 | E30: A - High Priority | F30: Not Started | J30: No
A31: Downers Grove | B31: IL | C31: DuPage | D31: 49000 | E31: A - High Priority | F31: Complete | J31: Yes | K31: AI Estimate (Not Verified)
A32: Glenview | B32: IL | C32: Cook | D32: 47000 | E32: A - High Priority | F32: Complete | J32: Yes | K32: AI Estimate (Not Verified)
A33: Elmhurst | B33: IL | C33: DuPage | D33: 46000 | E33: A - High Priority | F33: Complete | J33: Yes | K33: AI Estimate (Not Verified)
A34: Lombard | B34: IL | C34: DuPage | D34: 44000 | E34: A - High Priority | F34: Complete | J34: Yes | K34: AI Estimate (Not Verified)
A35: DeKalb | B35: IL | C35: DeKalb | D35: 44000 | E35: A - High Priority | F35: Not Started | J35: No
A36: Moline | B36: IL | C36: Rock Island | D36: 42000 | E36: A - High Priority | F36: Not Started | J36: No
A37: Belleville | B37: IL | C37: St. Clair | D37: 42000 | E37: A - High Priority | F37: Not Started | J37: No
A38: Plainfield | B38: IL | C38: Will | D38: 41000 | E38: A - High Priority | F38: Complete | J38: Yes | K38: AI Estimate (Not Verified)
A39: Bartlett | B39: IL | C39: Cook/DuPage | D39: 41000 | E39: A - High Priority | F39: Not Started | J39: No
A40: Buffalo Grove | B40: IL | C40: Lake/Cook | D40: 41000 | E40: A - High Priority | F40: Not Started | J40: No
...

Sheet Zoning Research
A1: Municipality | B1: State | C1: DT Zones Allowed | D1: DT Approval Pathway | E1: CW Zones Allowed | F1: CW Approval Pathway | G1: Zoning Code Score (0-20) | H1: Stacking Req (# cars) | I1: Lot Size Min (sq ft) | J1: Front Setback (ft) | K1: Side Setback (ft) | L1: Rear Setback (ft) | M1: Proximity Restrictions | N1: Hours Limits | O1: Traffic Study Req? | P1: Arch Review Req? | Q1: Site Req Score (0-20) | R1: Recent Approvals (3yr) | S1: Recent Denials (3yr) | T1: Avg Timeline (months) | U1: Est Approval Cost ($) | V1: Approval Score (0-20) | W1: # Existing Carwashes | X1: # DT Coffee Shops | Y1: # DT QSR Total | Z1: Saturation Score (0-20) | AA1: Board Receptivity | AB1: Moratorium? | AC1: Pending Ordinance Changes? | AD1: Notes | AE1: Political Score (0-20) | AF1: COMPOSITE SCORE | AG1: Override Score | AH1: Override Reason | AI1: Source URL 1 | AJ1: Source URL 2 | AK1: Confidence | AL1: Last Updated
A2: Chicago | B2: IL | G2: 18 | Q2: 18 | V2: 18 | Z2: 18 | AE2: 18 | AF2: =IF(AG2<>"",AG2,SUM(G2,Q2,V2,Z2,AE2)) -> 90 | AI2: AI Estimate
A3: Aurora | B3: IL | G3: 20 | Q3: 20 | V3: 20 | Z3: 20 | AE3: 20 | AF3: =IF(AG3<>"",AG3,SUM(G3,Q3,V3,Z3,AE3)) -> 100 | AI3: AI Estimate
A4: Naperville | B4: IL | D4: Conditional Use | F4: Conditional Use | G4: 12 | H4: 10 | Q4: 8 | R4: 1 | S4: 1 | V4: 5 | W4: 3 | X4: 2 | Z4: 8 | AA4: Hostile | AD4: City blocked Dutch Bros on Napier Blvd due to 7 Brew saturation at 1203 Iroquois. Board actively discouraging new DT coffee. | AE4: 5 | AF4: =IF(AG4<>"",AG4,SUM(G4,Q4,V4,Z4,AE4)) -> 38 | AI4: High
A5: Joliet | B5: IL | G5: 20 | Q5: 20 | V5: 20 | Z5: 20 | AE5: 20 | AF5: =IF(AG5<>"",AG5,SUM(G5,Q5,V5,Z5,AE5)) -> 100 | AI5: AI Estimate
A6: Rockford | B6: IL | AF6: =IF(AG6<>"",AG6,SUM(G6,Q6,V6,Z6,AE6)) -> 0
A7: Springfield | B7: IL | AF7: =IF(AG7<>"",AG7,SUM(G7,Q7,V7,Z7,AE7)) -> 0
A8: Elgin | B8: IL | AF8: =IF(AG8<>"",AG8,SUM(G8,Q8,V8,Z8,AE8)) -> 0
A9: Peoria | B9: IL | AF9: =IF(AG9<>"",AG9,SUM(G9,Q9,V9,Z9,AE9)) -> 0
A10: Champaign | B10: IL | AF10: =IF(AG10<>"",AG10,SUM(G10,Q10,V10,Z10,AE10)) -> 0
A11: Waukegan | B11: IL | G11: 20 | Q11: 20 | V11: 20 | Z11: 20 | AE11: 20 | AF11: =IF(AG11<>"",AG11,SUM(G11,Q11,V11,Z11,AE11)) -> 100 | AI11: AI Estimate
A12: Cicero | B12: IL | G12: 20 | Q12: 20 | V12: 20 | Z12: 20 | AE12: 20 | AF12: =IF(AG12<>"",AG12,SUM(G12,Q12,V12,Z12,AE12)) -> 100 | AI12: AI Estimate
A13: Bloomington | B13: IL | AF13: =IF(AG13<>"",AG13,SUM(G13,Q13,V13,Z13,AE13)) -> 0
A14: Arlington Heights | B14: IL | G14: 16 | Q14: 16 | V14: 16 | Z14: 16 | AE14: 16 | AF14: =IF(AG14<>"",AG14,SUM(G14,Q14,V14,Z14,AE14)) -> 80 | AI14: AI Estimate
A15: Evanston | B15: IL | G15: 16 | Q15: 16 | V15: 16 | Z15: 16 | AE15: 16 | AF15: =IF(AG15<>"",AG15,SUM(G15,Q15,V15,Z15,AE15)) -> 80 | AI15: AI Estimate
A16: Schaumburg | B16: IL | G16: 14 | Q16: 14 | V16: 14 | Z16: 14 | AE16: 14 | AF16: =IF(AG16<>"",AG16,SUM(G16,Q16,V16,Z16,AE16)) -> 70 | AI16: AI Estimate
A17: Bolingbrook | B17: IL | G17: 20 | Q17: 20 | V17: 20 | Z17: 20 | AE17: 20 | AF17: =IF(AG17<>"",AG17,SUM(G17,Q17,V17,Z17,AE17)) -> 100 | AI17: AI Estimate
A18: Decatur | B18: IL | AF18: =IF(AG18<>"",AG18,SUM(G18,Q18,V18,Z18,AE18)) -> 0
A19: Palatine | B19: IL | G19: 18 | Q19: 18 | V19: 18 | Z19: 18 | AE19: 18 | AF19: =IF(AG19<>"",AG19,SUM(G19,Q19,V19,Z19,AE19)) -> 90 | AI19: AI Estimate
A20: Skokie | B20: IL | G20: 18 | Q20: 18 | V20: 18 | Z20: 18 | AE20: 18 | AF20: =IF(AG20<>"",AG20,SUM(G20,Q20,V20,Z20,AE20)) -> 90 | AI20: AI Estimate
A21: Orland Park | B21: IL | G21: 18 | Q21: 18 | V21: 18 | Z21: 18 | AE21: 18 | AF21: =IF(AG21<>"",AG21,SUM(G21,Q21,V21,Z21,AE21)) -> 90 | AI21: AI Estimate
A22: Des Plaines | B22: IL | G22: 20 | Q22: 20 | V22: 20 | Z22: 20 | AE22: 20 | AF22: =IF(AG22<>"",AG22,SUM(G22,Q22,V22,Z22,AE22)) -> 100 | AI22: AI Estimate
A23: Tinley Park | B23: IL | G23: 20 | Q23: 20 | V23: 20 | Z23: 20 | AE23: 20 | AF23: =IF(AG23<>"",AG23,SUM(G23,Q23,V23,Z23,AE23)) -> 100 | AI23: AI Estimate
A24: Oak Lawn | B24: IL | AF24: =IF(AG24<>"",AG24,SUM(G24,Q24,V24,Z24,AE24)) -> 0
A25: Berwyn | B25: IL | G25: 20 | Q25: 20 | V25: 20 | Z25: 20 | AE25: 20 | AF25: =IF(AG25<>"",AG25,SUM(G25,Q25,V25,Z25,AE25)) -> 100 | AI25: AI Estimate
A26: Mount Prospect | B26: IL | G26: 18 | Q26: 18 | V26: 18 | Z26: 18 | AE26: 18 | AF26: =IF(AG26<>"",AG26,SUM(G26,Q26,V26,Z26,AE26)) -> 90 | AI26: AI Estimate
A27: Wheaton | B27: IL | G27: 18 | Q27: 18 | V27: 18 | Z27: 18 | AE27: 18 | AF27: =IF(AG27<>"",AG27,SUM(G27,Q27,V27,Z27,AE27)) -> 90 | AI27: AI Estimate
A28: Hoffman Estates | B28: IL | G28: 18 | Q28: 18 | V28: 18 | Z28: 18 | AE28: 18 | AF28: =IF(AG28<>"",AG28,SUM(G28,Q28,V28,Z28,AE28)) -> 90 | AI28: AI Estimate
A29: Oak Park | B29: IL | G29: 16 | Q29: 16 | V29: 16 | Z29: 16 | AE29: 16 | AF29: =IF(AG29<>"",AG29,SUM(G29,Q29,V29,Z29,AE29)) -> 80 | AI29: AI Estimate
A30: Normal | B30: IL | AF30: =IF(AG30<>"",AG30,SUM(G30,Q30,V30,Z30,AE30)) -> 0
A31: Downers Grove | B31: IL | G31: 16 | Q31: 16 | V31: 16 | Z31: 16 | AE31: 16 | AF31: =IF(AG31<>"",AG31,SUM(G31,Q31,V31,Z31,AE31)) -> 80 | AI31: AI Estimate
A32: Glenview | B32: IL | G32: 18 | Q32: 18 | V32: 18 | Z32: 18 | AE32: 18 | AF32: =IF(AG32<>"",AG32,SUM(G32,Q32,V32,Z32,AE32)) -> 90 | AI32: AI Estimate
A33: Elmhurst | B33: IL | G33: 18 | Q33: 18 | V33: 18 | Z33: 18 | AE33: 18 | AF33: =IF(AG33<>"",AG33,SUM(G33,Q33,V33,Z33,AE33)) -> 90 | AI33: AI Estimate
A34: Lombard | B34: IL | G34: 18 | Q34: 18 | V34: 18 | Z34: 18 | AE34: 18 | AF34: =IF(AG34<>"",AG34,SUM(G34,Q34,V34,Z34,AE34)) -> 90 | AI34: AI Estimate
A35: DeKalb | B35: IL | AF35: =IF(AG35<>"",AG35,SUM(G35,Q35,V35,Z35,AE35)) -> 0
A36: Moline | B36: IL | AF36: =IF(AG36<>"",AG36,SUM(G36,Q36,V36,Z36,AE36)) -> 0
A37: Belleville | B37: IL | AF37: =IF(AG37<>"",AG37,SUM(G37,Q37,V37,Z37,AE37)) -> 0
A38: Plainfield | B38: IL | G38: 20 | Q38: 20 | V38: 20 | Z38: 20 | AE38: 20 | AF38: =IF(AG38<>"",AG38,SUM(G38,Q38,V38,Z38,AE38)) -> 100 | AI38: AI Estimate
A39: Bartlett | B39: IL | AF39: =IF(AG39<>"",AG39,SUM(G39,Q39,V39,Z39,AE39)) -> 0
A40: Buffalo Grove | B40: IL | AF40: =IF(AG40<>"",AG40,SUM(G40,Q40,V40,Z40,AE40)) -> 0
...

Sheet Approval History
A1: Municipality | B1: State | C1: Project Name | D1: Applicant/Chain | E1: Use Type | F1: Date | G1: Outcome | H1: Conditions/Notes | I1: Source URL | J1: Entered By
A2: Naperville | B2: IL | C2: 7 Brew Coffee | D2: 7 Brew | E2: Drive-Thru Coffee | F2: 2024 | G2: Approved w/ Conditions | H2: 1203 Iroquois Road. Approved with extensive conditions. | J2: T. Ryan
A3: Naperville | B3: IL | C3: Dutch Bros Coffee | D3: Dutch Bros | E3: Drive-Thru Coffee | F3: 2025 | G3: Denied | H3: Napier Boulevard location. City not supportive due to 7 Brew saturation. | J3: T. Ryan

Sheet Competitive Landscape
A1: Municipality | B1: State | C1: Business Name | D1: Address | E1: Type | F1: Chain/Independent | G1: Year Opened (est) | H1: Source/Notes
A2: Naperville | B2: IL | C2: 7 Brew Coffee | D2: 1203 Iroquois Road | E2: Drive-Thru Coffee | F2: Chain (Blackstone-backed) | G2: 2024 | H2: Direct competitor. Blackstone growth equity investment Feb 2024. 600+ locations.

Sheet Score Calculator
A1: Municipality | B1: State | C1: Population | D1: Tier | E1: Zoning (0-20) | F1: Site Req (0-20) | G1: Approval (0-20) | H1: Saturation (0-20) | I1: Political (0-20) | J1: COMPOSITE | K1: Override | L1: Override Reason | M1: Confidence | N1: CW Score (old) | O1: DT Score (old) | P1: Delta
A2: Chicago | B2: IL | C2: 2700000 | D2: A | E2: ='Zoning Research'!G2 -> 18 | F2: ='Zoning Research'!Q2 -> 18 | G2: ='Zoning Research'!V2 -> 18 | H2: ='Zoning Research'!Z2 -> 18 | I2: ='Zoning Research'!AE2 -> 18 | J2: ='Zoning Research'!AF2 -> 90 | K2: ='Zoning Research'!AG2 -> 0 | L2: ='Zoning Research'!AH2 -> 0 | M2: ='Zoning Research'!AI2 -> AI Estimate | N2: 95 | O2: 85 | P2: =IF(J2="","",J2-AVERAGE(N2,O2)) -> 0
A3: Aurora | B3: IL | C3: 197000 | D3: A | E3: ='Zoning Research'!G3 -> 20 | F3: ='Zoning Research'!Q3 -> 20 | G3: ='Zoning Research'!V3 -> 20 | H3: ='Zoning Research'!Z3 -> 20 | I3: ='Zoning Research'!AE3 -> 20 | J3: ='Zoning Research'!AF3 -> 100 | K3: ='Zoning Research'!AG3 -> 0 | L3: ='Zoning Research'!AH3 -> 0 | M3: ='Zoning Research'!AI3 -> AI Estimate | N3: 100 | O3: 100 | P3: =IF(J3="","",J3-AVERAGE(N3,O3)) -> 0
A4: Naperville | B4: IL | C4: 149000 | D4: A | E4: ='Zoning Research'!G4 -> 12 | F4: ='Zoning Research'!Q4 -> 8 | G4: ='Zoning Research'!V4 -> 5 | H4: ='Zoning Research'!Z4 -> 8 | I4: ='Zoning Research'!AE4 -> 5 | J4: ='Zoning Research'!AF4 -> 38 | K4: ='Zoning Research'!AG4 -> 0 | L4: ='Zoning Research'!AH4 -> 0 | M4: ='Zoning Research'!AI4 -> High | N4: 75 | O4: 65 | P4: =IF(J4="","",J4-AVERAGE(N4,O4)) -> -32
A5: Joliet | B5: IL | C5: 148000 | D5: A | E5: ='Zoning Research'!G5 -> 20 | F5: ='Zoning Research'!Q5 -> 20 | G5: ='Zoning Research'!V5 -> 20 | H5: ='Zoning Research'!Z5 -> 20 | I5: ='Zoning Research'!AE5 -> 20 | J5: ='Zoning Research'!AF5 -> 100 | K5: ='Zoning Research'!AG5 -> 0 | L5: ='Zoning Research'!AH5 -> 0 | M5: ='Zoning Research'!AI5 -> AI Estimate | N5: 100 | O5: 100 | P5: =IF(J5="","",J5-AVERAGE(N5,O5)) -> 0
A6: Rockford | B6: IL | C6: 146000 | D6: A | E6: ='Zoning Research'!G6 -> 0 | F6: ='Zoning Research'!Q6 -> 0 | G6: ='Zoning Research'!V6 -> 0 | H6: ='Zoning Research'!Z6 -> 0 | I6: ='Zoning Research'!AE6 -> 0 | J6: ='Zoning Research'!AF6 -> 0 | K6: ='Zoning Research'!AG6 -> 0 | L6: ='Zoning Research'!AH6 -> 0 | M6: ='Zoning Research'!AI6 -> 0
A7: Springfield | B7: IL | C7: 114000 | D7: A | E7: ='Zoning Research'!G7 -> 0 | F7: ='Zoning Research'!Q7 -> 0 | G7: ='Zoning Research'!V7 -> 0 | H7: ='Zoning Research'!Z7 -> 0 | I7: ='Zoning Research'!AE7 -> 0 | J7: ='Zoning Research'!AF7 -> 0 | K7: ='Zoning Research'!AG7 -> 0 | L7: ='Zoning Research'!AH7 -> 0 | M7: ='Zoning Research'!AI7 -> 0
A8: Elgin | B8: IL | C8: 112000 | D8: A | E8: ='Zoning Research'!G8 -> 0 | F8: ='Zoning Research'!Q8 -> 0 | G8: ='Zoning Research'!V8 -> 0 | H8: ='Zoning Research'!Z8 -> 0 | I8: ='Zoning Research'!AE8 -> 0 | J8: ='Zoning Research'!AF8 -> 0 | K8: ='Zoning Research'!AG8 -> 0 | L8: ='Zoning Research'!AH8 -> 0 | M8: ='Zoning Research'!AI8 -> 0
A9: Peoria | B9: IL | C9: 110000 | D9: A | E9: ='Zoning Research'!G9 -> 0 | F9: ='Zoning Research'!Q9 -> 0 | G9: ='Zoning Research'!V9 -> 0 | H9: ='Zoning Research'!Z9 -> 0 | I9: ='Zoning Research'!AE9 -> 0 | J9: ='Zoning Research'!AF9 -> 0 | K9: ='Zoning Research'!AG9 -> 0 | L9: ='Zoning Research'!AH9 -> 0 | M9: ='Zoning Research'!AI9 -> 0
A10: Champaign | B10: IL | C10: 88000 | D10: A | E10: ='Zoning Research'!G10 -> 0 | F10: ='Zoning Research'!Q10 -> 0 | G10: ='Zoning Research'!V10 -> 0 | H10: ='Zoning Research'!Z10 -> 0 | I10: ='Zoning Research'!AE10 -> 0 | J10: ='Zoning Research'!AF10 -> 0 | K10: ='Zoning Research'!AG10 -> 0 | L10: ='Zoning Research'!AH10 -> 0 | M10: ='Zoning Research'!AI10 -> 0
A11: Waukegan | B11: IL | C11: 87000 | D11: A | E11: ='Zoning Research'!G11 -> 20 | F11: ='Zoning Research'!Q11 -> 20 | G11: ='Zoning Research'!V11 -> 20 | H11: ='Zoning Research'!Z11 -> 20 | I11: ='Zoning Research'!AE11 -> 20 | J11: ='Zoning Research'!AF11 -> 100 | K11: ='Zoning Research'!AG11 -> 0 | L11: ='Zoning Research'!AH11 -> 0 | M11: ='Zoning Research'!AI11 -> AI Estimate | N11: 100 | O11: 100 | P11: =IF(J11="","",J11-AVERAGE(N11,O11)) -> 0
A12: Cicero | B12: IL | C12: 84000 | D12: A | E12: ='Zoning Research'!G12 -> 20 | F12: ='Zoning Research'!Q12 -> 20 | G12: ='Zoning Research'!V12 -> 20 | H12: ='Zoning Research'!Z12 -> 20 | I12: ='Zoning Research'!AE12 -> 20 | J12: ='Zoning Research'!AF12 -> 100 | K12: ='Zoning Research'!AG12 -> 0 | L12: ='Zoning Research'!AH12 -> 0 | M12: ='Zoning Research'!AI12 -> AI Estimate | N12: 100 | O12: 100 | P12: =IF(J12="","",J12-AVERAGE(N12,O12)) -> 0
A13: Bloomington | B13: IL | C13: 78000 | D13: A | E13: ='Zoning Research'!G13 -> 0 | F13: ='Zoning Research'!Q13 -> 0 | G13: ='Zoning Research'!V13 -> 0 | H13: ='Zoning Research'!Z13 -> 0 | I13: ='Zoning Research'!AE13 -> 0 | J13: ='Zoning Research'!AF13 -> 0 | K13: ='Zoning Research'!AG13 -> 0 | L13: ='Zoning Research'!AH13 -> 0 | M13: ='Zoning Research'!AI13 -> 0
A14: Arlington Heights | B14: IL | C14: 76000 | D14: A | E14: ='Zoning Research'!G14 -> 16 | F14: ='Zoning Research'!Q14 -> 16 | G14: ='Zoning Research'!V14 -> 16 | H14: ='Zoning Research'!Z14 -> 16 | I14: ='Zoning Research'!AE14 -> 16 | J14: ='Zoning Research'!AF14 -> 80 | K14: ='Zoning Research'!AG14 -> 0 | L14: ='Zoning Research'!AH14 -> 0 | M14: ='Zoning Research'!AI14 -> AI Estimate | N14: 75 | O14: 85 | P14: =IF(J14="","",J14-AVERAGE(N14,O14)) -> 0
A15: Evanston | B15: IL | C15: 74000 | D15: A | E15: ='Zoning Research'!G15 -> 16 | F15: ='Zoning Research'!Q15 -> 16 | G15: ='Zoning Research'!V15 -> 16 | H15: ='Zoning Research'!Z15 -> 16 | I15: ='Zoning Research'!AE15 -> 16 | J15: ='Zoning Research'!AF15 -> 80 | K15: ='Zoning Research'!AG15 -> 0 | L15: ='Zoning Research'!AH15 -> 0 | M15: ='Zoning Research'!AI15 -> AI Estimate | N15: 65 | O15: 100 | P15: =IF(J15="","",J15-AVERAGE(N15,O15)) -> -2.5
A16: Schaumburg | B16: IL | C16: 74000 | D16: A | E16: ='Zoning Research'!G16 -> 14 | F16: ='Zoning Research'!Q16 -> 14 | G16: ='Zoning Research'!V16 -> 14 | H16: ='Zoning Research'!Z16 -> 14 | I16: ='Zoning Research'!AE16 -> 14 | J16: ='Zoning Research'!AF16 -> 70 | K16: ='Zoning Research'!AG16 -> 0 | L16: ='Zoning Research'!AH16 -> 0 | M16: ='Zoning Research'!AI16 -> AI Estimate | N16: 75 | O16: 65 | P16: =IF(J16="","",J16-AVERAGE(N16,O16)) -> 0
A17: Bolingbrook | B17: IL | C17: 73000 | D17: A | E17: ='Zoning Research'!G17 -> 20 | F17: ='Zoning Research'!Q17 -> 20 | G17: ='Zoning Research'!V17 -> 20 | H17: ='Zoning Research'!Z17 -> 20 | I17: ='Zoning Research'!AE17 -> 20 | J17: ='Zoning Research'!AF17 -> 100 | K17: ='Zoning Research'!AG17 -> 0 | L17: ='Zoning Research'!AH17 -> 0 | M17: ='Zoning Research'!AI17 -> AI Estimate | N17: 100 | O17: 100 | P17: =IF(J17="","",J17-AVERAGE(N17,O17)) -> 0
A18: Decatur | B18: IL | C18: 70000 | D18: A | E18: ='Zoning Research'!G18 -> 0 | F18: ='Zoning Research'!Q18 -> 0 | G18: ='Zoning Research'!V18 -> 0 | H18: ='Zoning Research'!Z18 -> 0 | I18: ='Zoning Research'!AE18 -> 0 | J18: ='Zoning Research'!AF18 -> 0 | K18: ='Zoning Research'!AG18 -> 0 | L18: ='Zoning Research'!AH18 -> 0 | M18: ='Zoning Research'!AI18 -> 0
A19: Palatine | B19: IL | C19: 68000 | D19: A | E19: ='Zoning Research'!G19 -> 18 | F19: ='Zoning Research'!Q19 -> 18 | G19: ='Zoning Research'!V19 -> 18 | H19: ='Zoning Research'!Z19 -> 18 | I19: ='Zoning Research'!AE19 -> 18 | J19: ='Zoning Research'!AF19 -> 90 | K19: ='Zoning Research'!AG19 -> 0 | L19: ='Zoning Research'!AH19 -> 0 | M19: ='Zoning Research'!AI19 -> AI Estimate | N19: 75 | O19: 100 | P19: =IF(J19="","",J19-AVERAGE(N19,O19)) -> 2.5
A20: Skokie | B20: IL | C20: 65000 | D20: A | E20: ='Zoning Research'!G20 -> 18 | F20: ='Zoning Research'!Q20 -> 18 | G20: ='Zoning Research'!V20 -> 18 | H20: ='Zoning Research'!Z20 -> 18 | I20: ='Zoning Research'!AE20 -> 18 | J20: ='Zoning Research'!AF20 -> 90 | K20: ='Zoning Research'!AG20 -> 0 | L20: ='Zoning Research'!AH20 -> 0 | M20: ='Zoning Research'!AI20 -> AI Estimate | N20: 75 | O20: 100 | P20: =IF(J20="","",J20-AVERAGE(N20,O20)) -> 2.5
A21: Orland Park | B21: IL | C21: 58000 | D21: A | E21: ='Zoning Research'!G21 -> 18 | F21: ='Zoning Research'!Q21 -> 18 | G21: ='Zoning Research'!V21 -> 18 | H21: ='Zoning Research'!Z21 -> 18 | I21: ='Zoning Research'!AE21 -> 18 | J21: ='Zoning Research'!AF21 -> 90 | K21: ='Zoning Research'!AG21 -> 0 | L21: ='Zoning Research'!AH21 -> 0 | M21: ='Zoning Research'!AI21 -> AI Estimate | N21: 75 | O21: 100 | P21: =IF(J21="","",J21-AVERAGE(N21,O21)) -> 2.5
A22: Des Plaines | B22: IL | C22: 58000 | D22: A | E22: ='Zoning Research'!G22 -> 20 | F22: ='Zoning Research'!Q22 -> 20 | G22: ='Zoning Research'!V22 -> 20 | H22: ='Zoning Research'!Z22 -> 20 | I22: ='Zoning Research'!AE22 -> 20 | J22: ='Zoning Research'!AF22 -> 100 | K22: ='Zoning Research'!AG22 -> 0 | L22: ='Zoning Research'!AH22 -> 0 | M22: ='Zoning Research'!AI22 -> AI Estimate | N22: 100 | O22: 100 | P22: =IF(J22="","",J22-AVERAGE(N22,O22)) -> 0
A23: Tinley Park | B23: IL | C23: 57000 | D23: A | E23: ='Zoning Research'!G23 -> 20 | F23: ='Zoning Research'!Q23 -> 20 | G23: ='Zoning Research'!V23 -> 20 | H23: ='Zoning Research'!Z23 -> 20 | I23: ='Zoning Research'!AE23 -> 20 | J23: ='Zoning Research'!AF23 -> 100 | K23: ='Zoning Research'!AG23 -> 0 | L23: ='Zoning Research'!AH23 -> 0 | M23: ='Zoning Research'!AI23 -> AI Estimate | N23: 100 | O23: 100 | P23: =IF(J23="","",J23-AVERAGE(N23,O23)) -> 0
A24: Oak Lawn | B24: IL | C24: 57000 | D24: A | E24: ='Zoning Research'!G24 -> 0 | F24: ='Zoning Research'!Q24 -> 0 | G24: ='Zoning Research'!V24 -> 0 | H24: ='Zoning Research'!Z24 -> 0 | I24: ='Zoning Research'!AE24 -> 0 | J24: ='Zoning Research'!AF24 -> 0 | K24: ='Zoning Research'!AG24 -> 0 | L24: ='Zoning Research'!AH24 -> 0 | M24: ='Zoning Research'!AI24 -> 0
A25: Berwyn | B25: IL | C25: 55000 | D25: A | E25: ='Zoning Research'!G25 -> 20 | F25: ='Zoning Research'!Q25 -> 20 | G25: ='Zoning Research'!V25 -> 20 | H25: ='Zoning Research'!Z25 -> 20 | I25: ='Zoning Research'!AE25 -> 20 | J25: ='Zoning Research'!AF25 -> 100 | K25: ='Zoning Research'!AG25 -> 0 | L25: ='Zoning Research'!AH25 -> 0 | M25: ='Zoning Research'!AI25 -> AI Estimate | N25: 100 | O25: 100 | P25: =IF(J25="","",J25-AVERAGE(N25,O25)) -> 0
A26: Mount Prospect | B26: IL | C26: 54000 | D26: A | E26: ='Zoning Research'!G26 -> 18 | F26: ='Zoning Research'!Q26 -> 18 | G26: ='Zoning Research'!V26 -> 18 | H26: ='Zoning Research'!Z26 -> 18 | I26: ='Zoning Research'!AE26 -> 18 | J26: ='Zoning Research'!AF26 -> 90 | K26: ='Zoning Research'!AG26 -> 0 | L26: ='Zoning Research'!AH26 -> 0 | M26: ='Zoning Research'!AI26 -> AI Estimate | N26: 75 | O26: 100 | P26: =IF(J26="","",J26-AVERAGE(N26,O26)) -> 2.5
A27: Wheaton | B27: IL | C27: 53000 | D27: A | E27: ='Zoning Research'!G27 -> 18 | F27: ='Zoning Research'!Q27 -> 18 | G27: ='Zoning Research'!V27 -> 18 | H27: ='Zoning Research'!Z27 -> 18 | I27: ='Zoning Research'!AE27 -> 18 | J27: ='Zoning Research'!AF27 -> 90 | K27: ='Zoning Research'!AG27 -> 0 | L27: ='Zoning Research'!AH27 -> 0 | M27: ='Zoning Research'!AI27 -> AI Estimate | N27: 75 | O27: 100 | P27: =IF(J27="","",J27-AVERAGE(N27,O27)) -> 2.5
A28: Hoffman Estates | B28: IL | C28: 52000 | D28: A | E28: ='Zoning Research'!G28 -> 18 | F28: ='Zoning Research'!Q28 -> 18 | G28: ='Zoning Research'!V28 -> 18 | H28: ='Zoning Research'!Z28 -> 18 | I28: ='Zoning Research'!AE28 -> 18 | J28: ='Zoning Research'!AF28 -> 90 | K28: ='Zoning Research'!AG28 -> 0 | L28: ='Zoning Research'!AH28 -> 0 | M28: ='Zoning Research'!AI28 -> AI Estimate | N28: 75 | O28: 100 | P28: =IF(J28="","",J28-AVERAGE(N28,O28)) -> 2.5
A29: Oak Park | B29: IL | C29: 52000 | D29: A | E29: ='Zoning Research'!G29 -> 16 | F29: ='Zoning Research'!Q29 -> 16 | G29: ='Zoning Research'!V29 -> 16 | H29: ='Zoning Research'!Z29 -> 16 | I29: ='Zoning Research'!AE29 -> 16 | J29: ='Zoning Research'!AF29 -> 80 | K29: ='Zoning Research'!AG29 -> 0 | L29: ='Zoning Research'!AH29 -> 0 | M29: ='Zoning Research'!AI29 -> AI Estimate | N29: 65 | O29: 100 | P29: =IF(J29="","",J29-AVERAGE(N29,O29)) -> -2.5
A30: Normal | B30: IL | C30: 52000 | D30: A | E30: ='Zoning Research'!G30 -> 0 | F30: ='Zoning Research'!Q30 -> 0 | G30: ='Zoning Research'!V30 -> 0 | H30: ='Zoning Research'!Z30 -> 0 | I30: ='Zoning Research'!AE30 -> 0 | J30: ='Zoning Research'!AF30 -> 0 | K30: ='Zoning Research'!AG30 -> 0 | L30: ='Zoning Research'!AH30 -> 0 | M30: ='Zoning Research'!AI30 -> 0
A31: Downers Grove | B31: IL | C31: 49000 | D31: A | E31: ='Zoning Research'!G31 -> 16 | F31: ='Zoning Research'!Q31 -> 16 | G31: ='Zoning Research'!V31 -> 16 | H31: ='Zoning Research'!Z31 -> 16 | I31: ='Zoning Research'!AE31 -> 16 | J31: ='Zoning Research'!AF31 -> 80 | K31: ='Zoning Research'!AG31 -> 0 | L31: ='Zoning Research'!AH31 -> 0 | M31: ='Zoning Research'!AI31 -> AI Estimate | N31: 75 | O31: 85 | P31: =IF(J31="","",J31-AVERAGE(N31,O31)) -> 0
A32: Glenview | B32: IL | C32: 47000 | D32: A | E32: ='Zoning Research'!G32 -> 18 | F32: ='Zoning Research'!Q32 -> 18 | G32: ='Zoning Research'!V32 -> 18 | H32: ='Zoning Research'!Z32 -> 18 | I32: ='Zoning Research'!AE32 -> 18 | J32: ='Zoning Research'!AF32 -> 90 | K32: ='Zoning Research'!AG32 -> 0 | L32: ='Zoning Research'!AH32 -> 0 | M32: ='Zoning Research'!AI32 -> AI Estimate | N32: 75 | O32: 100 | P32: =IF(J32="","",J32-AVERAGE(N32,O32)) -> 2.5
A33: Elmhurst | B33: IL | C33: 46000 | D33: A | E33: ='Zoning Research'!G33 -> 18 | F33: ='Zoning Research'!Q33 -> 18 | G33: ='Zoning Research'!V33 -> 18 | H33: ='Zoning Research'!Z33 -> 18 | I33: ='Zoning Research'!AE33 -> 18 | J33: ='Zoning Research'!AF33 -> 90 | K33: ='Zoning Research'!AG33 -> 0 | L33: ='Zoning Research'!AH33 -> 0 | M33: ='Zoning Research'!AI33 -> AI Estimate | N33: 75 | O33: 100 | P33: =IF(J33="","",J33-AVERAGE(N33,O33)) -> 2.5
A34: Lombard | B34: IL | C34: 44000 | D34: A | E34: ='Zoning Research'!G34 -> 18 | F34: ='Zoning Research'!Q34 -> 18 | G34: ='Zoning Research'!V34 -> 18 | H34: ='Zoning Research'!Z34 -> 18 | I34: ='Zoning Research'!AE34 -> 18 | J34: ='Zoning Research'!AF34 -> 90 | K34: ='Zoning Research'!AG34 -> 0 | L34: ='Zoning Research'!AH34 -> 0 | M34: ='Zoning Research'!AI34 -> AI Estimate | N34: 75 | O34: 100 | P34: =IF(J34="","",J34-AVERAGE(N34,O34)) -> 2.5
A35: DeKalb | B35: IL | C35: 44000 | D35: A | E35: ='Zoning Research'!G35 -> 0 | F35: ='Zoning Research'!Q35 -> 0 | G35: ='Zoning Research'!V35 -> 0 | H35: ='Zoning Research'!Z35 -> 0 | I35: ='Zoning Research'!AE35 -> 0 | J35: ='Zoning Research'!AF35 -> 0 | K35: ='Zoning Research'!AG35 -> 0 | L35: ='Zoning Research'!AH35 -> 0 | M35: ='Zoning Research'!AI35 -> 0
A36: Moline | B36: IL | C36: 42000 | D36: A | E36: ='Zoning Research'!G36 -> 0 | F36: ='Zoning Research'!Q36 -> 0 | G36: ='Zoning Research'!V36 -> 0 | H36: ='Zoning Research'!Z36 -> 0 | I36: ='Zoning Research'!AE36 -> 0 | J36: ='Zoning Research'!AF36 -> 0 | K36: ='Zoning Research'!AG36 -> 0 | L36: ='Zoning Research'!AH36 -> 0 | M36: ='Zoning Research'!AI36 -> 0
A37: Belleville | B37: IL | C37: 42000 | D37: A | E37: ='Zoning Research'!G37 -> 0 | F37: ='Zoning Research'!Q37 -> 0 | G37: ='Zoning Research'!V37 -> 0 | H37: ='Zoning Research'!Z37 -> 0 | I37: ='Zoning Research'!AE37 -> 0 | J37: ='Zoning Research'!AF37 -> 0 | K37: ='Zoning Research'!AG37 -> 0 | L37: ='Zoning Research'!AH37 -> 0 | M37: ='Zoning Research'!AI37 -> 0
A38: Plainfield | B38: IL | C38: 41000 | D38: A | E38: ='Zoning Research'!G38 -> 20 | F38: ='Zoning Research'!Q38 -> 20 | G38: ='Zoning Research'!V38 -> 20 | H38: ='Zoning Research'!Z38 -> 20 | I38: ='Zoning Research'!AE38 -> 20 | J38: ='Zoning Research'!AF38 -> 100 | K38: ='Zoning Research'!AG38 -> 0 | L38: ='Zoning Research'!AH38 -> 0 | M38: ='Zoning Research'!AI38 -> AI Estimate | N38: 100 | O38: 100 | P38: =IF(J38="","",J38-AVERAGE(N38,O38)) -> 0
A39: Bartlett | B39: IL | C39: 41000 | D39: A | E39: ='Zoning Research'!G39 -> 0 | F39: ='Zoning Research'!Q39 -> 0 | G39: ='Zoning Research'!V39 -> 0 | H39: ='Zoning Research'!Z39 -> 0 | I39: ='Zoning Research'!AE39 -> 0 | J39: ='Zoning Research'!AF39 -> 0 | K39: ='Zoning Research'!AG39 -> 0 | L39: ='Zoning Research'!AH39 -> 0 | M39: ='Zoning Research'!AI39 -> 0
A40: Buffalo Grove | B40: IL | C40: 41000 | D40: A | E40: ='Zoning Research'!G40 -> 0 | F40: ='Zoning Research'!Q40 -> 0 | G40: ='Zoning Research'!V40 -> 0 | H40: ='Zoning Research'!Z40 -> 0 | I40: ='Zoning Research'!AE40 -> 0 | J40: ='Zoning Research'!AF40 -> 0 | K40: ='Zoning Research'!AG40 -> 0 | L40: ='Zoning Research'!AH40 -> 0 | M40: ='Zoning Research'!AI40 -> 0
...

Sheet Ground Truth
A1: Municipality | B1: State | C1: Use Type | D1: Our Score at Time | E1: Actual Outcome | F1: Date | G1: Predicted Correctly? | H1: Lesson Learned | I1: Score Adjustment Made?
A2: Naperville | B2: IL | C2: Drive-Thru Coffee | D2: 65 | E2: DENIED - City blocked Dutch Bros on Napier Blvd | F2: 2025 | G2: No | H2: Old AI score of 65 was too high. Real score ~38. City hostile to new DT coffee after 7 Brew approval. Saturation + political resistance not captured by zoning code analysis alone. | I2: Yes - dropped to 38
